Traceback (most recent call last):
  File "/opt/hostedtoolcache/Python/3.8.16/x64/lib/python3.8/site-packages/jupyter_cache/executors/utils.py", line 51, in single_nb_execution
    executenb(
  File "/opt/hostedtoolcache/Python/3.8.16/x64/lib/python3.8/site-packages/nbclient/client.py", line 1204, in execute
    return NotebookClient(nb=nb, resources=resources, km=km, **kwargs).execute()
  File "/opt/hostedtoolcache/Python/3.8.16/x64/lib/python3.8/site-packages/nbclient/util.py", line 84, in wrapped
    return just_run(coro(*args, **kwargs))
  File "/opt/hostedtoolcache/Python/3.8.16/x64/lib/python3.8/site-packages/nbclient/util.py", line 62, in just_run
    return loop.run_until_complete(coro)
  File "/opt/hostedtoolcache/Python/3.8.16/x64/lib/python3.8/asyncio/base_events.py", line 616, in run_until_complete
    return future.result()
  File "/opt/hostedtoolcache/Python/3.8.16/x64/lib/python3.8/site-packages/nbclient/client.py", line 663, in async_execute
    await self.async_execute_cell(
  File "/opt/hostedtoolcache/Python/3.8.16/x64/lib/python3.8/site-packages/nbclient/client.py", line 965, in async_execute_cell
    await self._check_raise_for_error(cell, cell_index, exec_reply)
  File "/opt/hostedtoolcache/Python/3.8.16/x64/lib/python3.8/site-packages/nbclient/client.py", line 862, in _check_raise_for_error
    raise CellExecutionError.from_cell_and_msg(cell, exec_reply_content)
nbclient.exceptions.CellExecutionError: An error occurred while executing the following cell:
------------------
ta_trial_data = []

for t in range(5000):
    ta_y_pred = ta_x.mm( ta_w1 ).clamp( min=0 ).mm(ta_w2)
    
    ta_loss = (ta_y_pred - ta_y).pow(2).sum()
#     print(t, ta_loss.data[0])
    
    ta_loss.backward()
    
    ta_w1.data -= learning_rate* ta_w1.grad.data
    ta_w2.data -= learning_rate* ta_w2.grad.data
    
    ta_w1.grad.data.zero_()
    ta_w2.grad.data.zero_()
    
    ta_trial_data.append( [t, ta_loss.data[0]] )

# print(t, ta_loss.data[0])


------------------

[0;31m---------------------------------------------------------------------------[0m
[0;31mIndexError[0m                                Traceback (most recent call last)
Cell [0;32mIn[7], line 17[0m
[1;32m     14[0m     ta_w1[38;5;241m.[39mgrad[38;5;241m.[39mdata[38;5;241m.[39mzero_()
[1;32m     15[0m     ta_w2[38;5;241m.[39mgrad[38;5;241m.[39mdata[38;5;241m.[39mzero_()
[0;32m---> 17[0m     ta_trial_data[38;5;241m.[39mappend( [t, [43mta_loss[49m[38;5;241;43m.[39;49m[43mdata[49m[43m[[49m[38;5;241;43m0[39;49m[43m][49m] )
[1;32m     19[0m [38;5;66;03m# print(t, ta_loss.data[0])[39;00m

[0;31mIndexError[0m: invalid index of a 0-dim tensor. Use `tensor.item()` in Python or `tensor.item<T>()` in C++ to convert a 0-dim tensor to a number
IndexError: invalid index of a 0-dim tensor. Use `tensor.item()` in Python or `tensor.item<T>()` in C++ to convert a 0-dim tensor to a number

